<robot name="car">
  <link name="base_link">
    <inertial>
      <origin xyz="0 0 1"/>
      <mass value="1000.0"/>
      <inertia ixx="500.0" ixy="0.0" ixz="0.0" iyy="500.0" iyz="0.0" izz="1000.0"/>
    </inertial>
    <visual>
      <origin xyz="0 0 1"/>
      <geometry>
        <box size="10 5 2.5"/>
      </geometry>
    </visual>
    <collision>
      <origin xyz="0 0 1"/>
      <geometry>
        <box size="10 5 2.5"/>
      </geometry>
    </collision>
  </link>

  <!-- Definizione delle ruote -->
  <link name="wheel_link_fl">
    <inertial>
      <origin xyz="0 0 0" rpy="1.57 0 0"/>
      <mass value="20.0"/>
      <inertia ixx="1.0" ixy="0.0" ixz="0.0" iyy="1.0" iyz="0.0" izz="1.0"/>
    </inertial>
    <visual>
      <origin xyz="0 0 0" rpy="1.57 0 0"/>
      <geometry>
        <cylinder radius="1" length="0.5"/>
      </geometry>
    </visual>
    <collision>
      <origin xyz="0 0 0" rpy="1.57 0 0"/>
      <geometry>
        <cylinder radius="1" length="0.5"/>
      </geometry>
    </collision>
  </link>
  

  <link name="wheel_link_fr">
    <inertial>
      <origin xyz="0 0 0" rpy="1.57 0 0"/>
      <mass value="20.0"/>
      <inertia ixx="1.0" ixy="0.0" ixz="0.0" iyy="1.0" iyz="0.0" izz="1.0"/>
    </inertial>
    <visual>
      <origin xyz="0 0 0" rpy="1.57 0 0"/>
      <geometry>
        <cylinder radius="1" length="0.5"/>
      </geometry>
    </visual>
    <collision>
      <origin xyz="0 0 0" rpy="1.57 0 0"/>
      <geometry>
        <cylinder radius="1" length="0.5"/>
      </geometry>
    </collision>
  </link>


  <link name="wheel_link_rl">
    <inertial>
      <origin xyz="0 0 0" rpy="1.57 0 0"/>
      <mass value="20.0"/>
      <inertia ixx="1.0" ixy="0.0" ixz="0.0" iyy="1.0" iyz="0.0" izz="1.0"/>
    </inertial>
    <visual>
      <origin xyz="0 0 0" rpy="1.57 0 0"/>
      <geometry>
        <cylinder radius="1" length="0.5"/>
      </geometry>
    </visual>
    <collision>
      <origin xyz="0 0 0" rpy="1.57 0 0"/>
      <geometry>
        <cylinder radius="1" length="0.5"/>
      </geometry>
    </collision>
  </link>


  <link name="wheel_link_rr">
    <inertial>
      <origin xyz="0 0 0" rpy="1.57 0 0"/>
      <mass value="20.0"/>
      <inertia ixx="1.0" ixy="0.0" ixz="0.0" iyy="1.0" iyz="0.0" izz="1.0"/>
    </inertial>
    <visual>
      <origin xyz="0 0 0" rpy="1.57 0 0"/>
      <geometry>
        <cylinder radius="1" length="0.5"/>
      </geometry>
    </visual>
    <collision>
      <origin xyz="0 0 0" rpy="1.57 0 0"/>
      <geometry>
        <cylinder radius="1" length="0.5"/>
      </geometry>
    </collision>
  </link>



  <!-- Giunti per le ruote -->
  <joint name="joint_fl" type="continuous">
    <parent link="base_link"/>
    <child link="wheel_link_fl"/>
    <origin xyz="2.5 2.80 0" rpy="0 0 0"/>
    <axis xyz="0 1 0"/>
  </joint>
  
  <joint name="joint_fr" type="continuous">
    <parent link="base_link"/>
    <child link="wheel_link_fr"/>
    <origin xyz="2.5 -2.80 0" rpy="0 0 0"/>
    <axis xyz="0 1 0"/>
  </joint>

  <joint name="joint_rl" type="continuous">
    <parent link="base_link"/>
    <child link="wheel_link_rl"/>
    <origin xyz="-2.5 2.80 0" rpy="0 0 0"/>
    <axis xyz="0 1 0"/>
  </joint>

  <joint name="joint_rr" type="continuous">
    <parent link="base_link"/>
    <child link="wheel_link_rr"/>
    <origin xyz="-2.5 -2.80 0" rpy="0 0 0"/>
    <axis xyz="0 1 0"/>
  </joint>


  <gazebo reference="base_link">
    <material>Gazebo/Red</material>
  </gazebo>


  <gazebo reference="wheel_link_fl">
    <material>Gazebo/Blue</material>
  </gazebo>

  <gazebo reference="wheel_link_fr">
    <material>Gazebo/Blue</material>
  </gazebo>

  <gazebo reference="wheel_link_rl">
    <material>Gazebo/Blue</material>
  </gazebo>

  <gazebo reference="wheel_link_rr">
    <material>Gazebo/Blue</material>
  </gazebo>
 
</robot>

